[2025-07-19T21:30:42.800+0000] {local_task_job_runner.py:120} INFO - ::group::Pre task execution logs
[2025-07-19T21:30:42.876+0000] {taskinstance.py:2076} INFO - Dependencies all met for dep_context=non-requeueable deps ti=<TaskInstance: nog_weekly_prediction.force_data_update manual__2025-07-19T21:30:37+00:00 [queued]>
[2025-07-19T21:30:42.904+0000] {taskinstance.py:2076} INFO - Dependencies all met for dep_context=requeueable deps ti=<TaskInstance: nog_weekly_prediction.force_data_update manual__2025-07-19T21:30:37+00:00 [queued]>
[2025-07-19T21:30:42.906+0000] {taskinstance.py:2306} INFO - Starting attempt 1 of 2
[2025-07-19T21:30:42.961+0000] {taskinstance.py:2330} INFO - Executing <Task(PythonOperator): force_data_update> on 2025-07-19 21:30:37+00:00
[2025-07-19T21:30:42.992+0000] {standard_task_runner.py:63} INFO - Started process 203 to run task
[2025-07-19T21:30:43.002+0000] {standard_task_runner.py:90} INFO - Running: ['***', 'tasks', 'run', 'nog_weekly_prediction', 'force_data_update', 'manual__2025-07-19T21:30:37+00:00', '--job-id', '14', '--raw', '--subdir', 'DAGS_FOLDER/nog_weekly_prediction_dag.py', '--cfg-path', '/tmp/tmpqmk_3lbv']
[2025-07-19T21:30:43.014+0000] {standard_task_runner.py:91} INFO - Job 14: Subtask force_data_update
[2025-07-19T21:30:43.242+0000] {task_command.py:426} INFO - Running <TaskInstance: nog_weekly_prediction.force_data_update manual__2025-07-19T21:30:37+00:00 [running]> on host 4f96241099ed
[2025-07-19T21:30:43.435+0000] {taskinstance.py:2648} INFO - Exporting env vars: AIRFLOW_CTX_DAG_EMAIL='ketaki.kolhatkar99@gmail.com' AIRFLOW_CTX_DAG_OWNER='nog_team' AIRFLOW_CTX_DAG_ID='nog_weekly_prediction' AIRFLOW_CTX_TASK_ID='force_data_update' AIRFLOW_CTX_EXECUTION_DATE='2025-07-19T21:30:37+00:00' AIRFLOW_CTX_TRY_NUMBER='1' AIRFLOW_CTX_DAG_RUN_ID='manual__2025-07-19T21:30:37+00:00'
[2025-07-19T21:30:43.440+0000] {taskinstance.py:430} INFO - ::endgroup::
[2025-07-19T21:30:43.504+0000] {nog_weekly_prediction_dag.py:85} INFO - üîÑ Forcing data update...
[2025-07-19T21:30:43.505+0000] {weekly_predict.py:336} INFO - Starting weekly prediction pipeline...
[2025-07-19T21:30:43.506+0000] {weekly_predict.py:112} INFO - Fetching data (update_csv=True)...
[2025-07-19T21:30:43.514+0000] {weekly_predict.py:120} ERROR - Error fetching data: [Errno 2] No such file or directory: 'data/NOG.csv'
[2025-07-19T21:30:43.515+0000] {weekly_predict.py:377} ERROR - Pipeline failed: [Errno 2] No such file or directory: 'data/NOG.csv'
[2025-07-19T21:30:43.515+0000] {nog_weekly_prediction_dag.py:99} ERROR - ‚ùå Forced update failed: [Errno 2] No such file or directory: 'data/NOG.csv'
[2025-07-19T21:30:43.516+0000] {nog_weekly_prediction_dag.py:103} ERROR - ‚ùå Error in forced data update: Forced update failed: [Errno 2] No such file or directory: 'data/NOG.csv'
[2025-07-19T21:30:43.516+0000] {taskinstance.py:441} INFO - ::group::Post task execution logs
[2025-07-19T21:30:43.517+0000] {taskinstance.py:2905} ERROR - Task failed with exception
Traceback (most recent call last):
  File "/home/airflow/.local/lib/python3.12/site-packages/airflow/models/taskinstance.py", line 465, in _execute_task
    result = _execute_callable(context=context, **execute_callable_kwargs)
             ^^^^^^^^^^^^^^^^^^^^^^^^^^^^^^^^^^^^^^^^^^^^^^^^^^^^^^^^^^^^^
  File "/home/airflow/.local/lib/python3.12/site-packages/airflow/models/taskinstance.py", line 432, in _execute_callable
    return execute_callable(context=context, **execute_callable_kwargs)
           ^^^^^^^^^^^^^^^^^^^^^^^^^^^^^^^^^^^^^^^^^^^^^^^^^^^^^^^^^^^^
  File "/home/airflow/.local/lib/python3.12/site-packages/airflow/models/baseoperator.py", line 400, in wrapper
    return func(self, *args, **kwargs)
           ^^^^^^^^^^^^^^^^^^^^^^^^^^^
  File "/home/airflow/.local/lib/python3.12/site-packages/airflow/operators/python.py", line 235, in execute
    return_value = self.execute_callable()
                   ^^^^^^^^^^^^^^^^^^^^^^^
  File "/home/airflow/.local/lib/python3.12/site-packages/airflow/operators/python.py", line 252, in execute_callable
    return self.python_callable(*self.op_args, **self.op_kwargs)
           ^^^^^^^^^^^^^^^^^^^^^^^^^^^^^^^^^^^^^^^^^^^^^^^^^^^^^
  File "/opt/airflow/dags/nog_weekly_prediction_dag.py", line 100, in force_data_update
    raise Exception(error_msg)
Exception: Forced update failed: [Errno 2] No such file or directory: 'data/NOG.csv'
[2025-07-19T21:30:43.535+0000] {taskinstance.py:1206} INFO - Marking task as UP_FOR_RETRY. dag_id=nog_weekly_prediction, task_id=force_data_update, run_id=manual__2025-07-19T21:30:37+00:00, execution_date=20250719T213037, start_date=20250719T213042, end_date=20250719T213043
[2025-07-19T21:30:43.550+0000] {standard_task_runner.py:110} ERROR - Failed to execute job 14 for task force_data_update (Forced update failed: [Errno 2] No such file or directory: 'data/NOG.csv'; 203)
[2025-07-19T21:30:43.601+0000] {local_task_job_runner.py:240} INFO - Task exited with return code 1
[2025-07-19T21:30:43.698+0000] {taskinstance.py:3498} INFO - 0 downstream tasks scheduled from follow-on schedule check
[2025-07-19T21:30:43.701+0000] {local_task_job_runner.py:222} INFO - ::endgroup::
