[2025-07-19T21:35:47.220+0000] {local_task_job_runner.py:120} INFO - ::group::Pre task execution logs
[2025-07-19T21:35:47.285+0000] {taskinstance.py:2076} INFO - Dependencies all met for dep_context=non-requeueable deps ti=<TaskInstance: nog_weekly_prediction.force_data_update manual__2025-07-19T21:30:37+00:00 [queued]>
[2025-07-19T21:35:47.295+0000] {taskinstance.py:2076} INFO - Dependencies all met for dep_context=requeueable deps ti=<TaskInstance: nog_weekly_prediction.force_data_update manual__2025-07-19T21:30:37+00:00 [queued]>
[2025-07-19T21:35:47.295+0000] {taskinstance.py:2306} INFO - Starting attempt 2 of 2
[2025-07-19T21:35:47.307+0000] {taskinstance.py:2330} INFO - Executing <Task(PythonOperator): force_data_update> on 2025-07-19 21:30:37+00:00
[2025-07-19T21:35:47.321+0000] {standard_task_runner.py:63} INFO - Started process 410 to run task
[2025-07-19T21:35:47.329+0000] {standard_task_runner.py:90} INFO - Running: ['***', 'tasks', 'run', 'nog_weekly_prediction', 'force_data_update', 'manual__2025-07-19T21:30:37+00:00', '--job-id', '19', '--raw', '--subdir', 'DAGS_FOLDER/nog_weekly_prediction_dag.py', '--cfg-path', '/tmp/tmpmh99e4a3']
[2025-07-19T21:35:47.333+0000] {standard_task_runner.py:91} INFO - Job 19: Subtask force_data_update
[2025-07-19T21:35:47.492+0000] {task_command.py:426} INFO - Running <TaskInstance: nog_weekly_prediction.force_data_update manual__2025-07-19T21:30:37+00:00 [running]> on host 4f96241099ed
[2025-07-19T21:35:47.741+0000] {taskinstance.py:2648} INFO - Exporting env vars: AIRFLOW_CTX_DAG_EMAIL='ketaki.kolhatkar99@gmail.com' AIRFLOW_CTX_DAG_OWNER='nog_team' AIRFLOW_CTX_DAG_ID='nog_weekly_prediction' AIRFLOW_CTX_TASK_ID='force_data_update' AIRFLOW_CTX_EXECUTION_DATE='2025-07-19T21:30:37+00:00' AIRFLOW_CTX_TRY_NUMBER='2' AIRFLOW_CTX_DAG_RUN_ID='manual__2025-07-19T21:30:37+00:00'
[2025-07-19T21:35:47.745+0000] {taskinstance.py:430} INFO - ::endgroup::
[2025-07-19T21:35:47.792+0000] {nog_weekly_prediction_dag.py:85} INFO - üîÑ Forcing data update...
[2025-07-19T21:35:47.795+0000] {weekly_predict.py:336} INFO - Starting weekly prediction pipeline...
[2025-07-19T21:35:47.797+0000] {weekly_predict.py:112} INFO - Fetching data (update_csv=True)...
[2025-07-19T21:35:47.938+0000] {logging_mixin.py:188} INFO - [INFO] Loaded 501 existing news articles
[2025-07-19T21:35:47.940+0000] {logging_mixin.py:188} INFO - [INFO] Fetching news for query: 'Northern Oil and Gas'
[2025-07-19T21:36:22.405+0000] {logging_mixin.py:188} INFO - [INFO] Fetching news for query: 'NOG stock'
[2025-07-19T21:36:32.728+0000] {logging_mixin.py:188} INFO - [INFO] Fetching news for query: 'Northern Oil and Gas earnings'
[2025-07-19T21:36:52.461+0000] {logging_mixin.py:188} INFO - [INFO] Fetching news for query: 'Northern Oil & Gas Inc'
[2025-07-19T21:37:54.316+0000] {logging_mixin.py:188} INFO - [INFO] Fetching news for query: 'NOG Q1 results'
[2025-07-19T21:37:55.647+0000] {logging_mixin.py:188} INFO - [INFO] Fetching news for query: 'NOG Q2 results'
[2025-07-19T21:37:56.864+0000] {logging_mixin.py:188} INFO - [INFO] Fetching news for query: 'NOG Q3 results'
[2025-07-19T21:37:58.485+0000] {logging_mixin.py:188} INFO - [INFO] Fetching news for query: 'NOG Q4 results'
[2025-07-19T21:37:59.800+0000] {logging_mixin.py:188} INFO - [INFO] Fetching news for query: 'NOG quarterly report'
[2025-07-19T21:38:03.966+0000] {logging_mixin.py:188} INFO - [INFO] Fetching news for query: 'Northern Oil and Gas acquisition'
[2025-07-19T21:38:10.522+0000] {logging_mixin.py:188} INFO - [INFO] Fetching news for query: 'NOG financial results'
[2025-07-19T21:38:11.721+0000] {logging_mixin.py:188} INFO - [INFO] Fetching news for query: 'Northern Oil and Gas dividend'
[2025-07-19T21:38:26.755+0000] {logging_mixin.py:188} INFO - [INFO] Fetched 171 new news articles
[2025-07-19T21:38:26.796+0000] {logging_mixin.py:188} INFO - [INFO] Saved 501 total news articles to data/NOG_news_2years.csv
[2025-07-19T21:38:27.112+0000] {logging_mixin.py:188} INFO - [INFO] Created 501 enhanced news chunks
[2025-07-19T21:38:27.879+0000] {logging_mixin.py:188} WARNING - [*********************100%***********************]  1 of 1 completed
[2025-07-19T21:38:28.636+0000] {weekly_predict.py:116} INFO - Successfully fetched data with shape: (0, 19)
[2025-07-19T21:38:28.646+0000] {weekly_predict.py:157} INFO - Training weekly model...
[2025-07-19T21:38:28.663+0000] {weekly_predict.py:377} ERROR - Pipeline failed: With n_samples=0, test_size=0.2 and train_size=None, the resulting train set will be empty. Adjust any of the aforementioned parameters.
[2025-07-19T21:38:28.675+0000] {nog_weekly_prediction_dag.py:99} ERROR - ‚ùå Forced update failed: With n_samples=0, test_size=0.2 and train_size=None, the resulting train set will be empty. Adjust any of the aforementioned parameters.
[2025-07-19T21:38:28.679+0000] {nog_weekly_prediction_dag.py:103} ERROR - ‚ùå Error in forced data update: Forced update failed: With n_samples=0, test_size=0.2 and train_size=None, the resulting train set will be empty. Adjust any of the aforementioned parameters.
[2025-07-19T21:38:28.682+0000] {taskinstance.py:441} INFO - ::group::Post task execution logs
[2025-07-19T21:38:28.830+0000] {taskinstance.py:2905} ERROR - Task failed with exception
Traceback (most recent call last):
  File "/home/airflow/.local/lib/python3.12/site-packages/airflow/models/taskinstance.py", line 465, in _execute_task
    result = _execute_callable(context=context, **execute_callable_kwargs)
             ^^^^^^^^^^^^^^^^^^^^^^^^^^^^^^^^^^^^^^^^^^^^^^^^^^^^^^^^^^^^^
  File "/home/airflow/.local/lib/python3.12/site-packages/airflow/models/taskinstance.py", line 432, in _execute_callable
    return execute_callable(context=context, **execute_callable_kwargs)
           ^^^^^^^^^^^^^^^^^^^^^^^^^^^^^^^^^^^^^^^^^^^^^^^^^^^^^^^^^^^^
  File "/home/airflow/.local/lib/python3.12/site-packages/airflow/models/baseoperator.py", line 400, in wrapper
    return func(self, *args, **kwargs)
           ^^^^^^^^^^^^^^^^^^^^^^^^^^^
  File "/home/airflow/.local/lib/python3.12/site-packages/airflow/operators/python.py", line 235, in execute
    return_value = self.execute_callable()
                   ^^^^^^^^^^^^^^^^^^^^^^^
  File "/home/airflow/.local/lib/python3.12/site-packages/airflow/operators/python.py", line 252, in execute_callable
    return self.python_callable(*self.op_args, **self.op_kwargs)
           ^^^^^^^^^^^^^^^^^^^^^^^^^^^^^^^^^^^^^^^^^^^^^^^^^^^^^
  File "/opt/airflow/dags/nog_weekly_prediction_dag.py", line 100, in force_data_update
    raise Exception(error_msg)
Exception: Forced update failed: With n_samples=0, test_size=0.2 and train_size=None, the resulting train set will be empty. Adjust any of the aforementioned parameters.
[2025-07-19T21:38:29.138+0000] {taskinstance.py:1206} INFO - Marking task as FAILED. dag_id=nog_weekly_prediction, task_id=force_data_update, run_id=manual__2025-07-19T21:30:37+00:00, execution_date=20250719T213037, start_date=20250719T213547, end_date=20250719T213829
[2025-07-19T21:38:29.290+0000] {configuration.py:1050} WARNING - section/key [smtp/smtp_user] not found in config
[2025-07-19T21:38:29.293+0000] {email.py:271} INFO - Email alerting: attempt 1
[2025-07-19T21:38:29.327+0000] {configuration.py:1050} WARNING - section/key [smtp/smtp_user] not found in config
[2025-07-19T21:38:29.330+0000] {email.py:271} INFO - Email alerting: attempt 1
[2025-07-19T21:38:29.336+0000] {taskinstance.py:879} ERROR - Failed to send email to: ['ketaki.kolhatkar99@gmail.com']
Traceback (most recent call last):
  File "/home/airflow/.local/lib/python3.12/site-packages/airflow/models/taskinstance.py", line 2479, in _run_raw_task
    self._execute_task_with_callbacks(context, test_mode, session=session)
  File "/home/airflow/.local/lib/python3.12/site-packages/airflow/models/taskinstance.py", line 2676, in _execute_task_with_callbacks
    result = self._execute_task(context, task_orig)
             ^^^^^^^^^^^^^^^^^^^^^^^^^^^^^^^^^^^^^^
  File "/home/airflow/.local/lib/python3.12/site-packages/airflow/models/taskinstance.py", line 2701, in _execute_task
    return _execute_task(self, context, task_orig)
           ^^^^^^^^^^^^^^^^^^^^^^^^^^^^^^^^^^^^^^^
  File "/home/airflow/.local/lib/python3.12/site-packages/airflow/models/taskinstance.py", line 465, in _execute_task
    result = _execute_callable(context=context, **execute_callable_kwargs)
             ^^^^^^^^^^^^^^^^^^^^^^^^^^^^^^^^^^^^^^^^^^^^^^^^^^^^^^^^^^^^^
  File "/home/airflow/.local/lib/python3.12/site-packages/airflow/models/taskinstance.py", line 432, in _execute_callable
    return execute_callable(context=context, **execute_callable_kwargs)
           ^^^^^^^^^^^^^^^^^^^^^^^^^^^^^^^^^^^^^^^^^^^^^^^^^^^^^^^^^^^^
  File "/home/airflow/.local/lib/python3.12/site-packages/airflow/models/baseoperator.py", line 400, in wrapper
    return func(self, *args, **kwargs)
           ^^^^^^^^^^^^^^^^^^^^^^^^^^^
  File "/home/airflow/.local/lib/python3.12/site-packages/airflow/operators/python.py", line 235, in execute
    return_value = self.execute_callable()
                   ^^^^^^^^^^^^^^^^^^^^^^^
  File "/home/airflow/.local/lib/python3.12/site-packages/airflow/operators/python.py", line 252, in execute_callable
    return self.python_callable(*self.op_args, **self.op_kwargs)
           ^^^^^^^^^^^^^^^^^^^^^^^^^^^^^^^^^^^^^^^^^^^^^^^^^^^^^
  File "/opt/airflow/dags/nog_weekly_prediction_dag.py", line 100, in force_data_update
    raise Exception(error_msg)
Exception: Forced update failed: With n_samples=0, test_size=0.2 and train_size=None, the resulting train set will be empty. Adjust any of the aforementioned parameters.

During handling of the above exception, another exception occurred:

Traceback (most recent call last):
  File "/home/airflow/.local/lib/python3.12/site-packages/airflow/models/taskinstance.py", line 1063, in _email_alert
    send_email(task.email, subject, html_content)
  File "/home/airflow/.local/lib/python3.12/site-packages/airflow/utils/email.py", line 80, in send_email
    return backend(
           ^^^^^^^^
  File "/home/airflow/.local/lib/python3.12/site-packages/airflow/utils/email.py", line 154, in send_email_smtp
    send_mime_email(e_from=mail_from, e_to=recipients, mime_msg=msg, conn_id=conn_id, dryrun=dryrun)
  File "/home/airflow/.local/lib/python3.12/site-packages/airflow/utils/email.py", line 273, in send_mime_email
    smtp_conn = _get_smtp_connection(smtp_host, smtp_port, smtp_timeout, smtp_ssl)
                ^^^^^^^^^^^^^^^^^^^^^^^^^^^^^^^^^^^^^^^^^^^^^^^^^^^^^^^^^^^^^^^^^^
  File "/home/airflow/.local/lib/python3.12/site-packages/airflow/utils/email.py", line 317, in _get_smtp_connection
    return smtplib.SMTP(host=host, port=port, timeout=timeout)
           ^^^^^^^^^^^^^^^^^^^^^^^^^^^^^^^^^^^^^^^^^^^^^^^^^^^
  File "/usr/local/lib/python3.12/smtplib.py", line 255, in __init__
    (code, msg) = self.connect(host, port)
                  ^^^^^^^^^^^^^^^^^^^^^^^^
  File "/usr/local/lib/python3.12/smtplib.py", line 341, in connect
    self.sock = self._get_socket(host, port, self.timeout)
                ^^^^^^^^^^^^^^^^^^^^^^^^^^^^^^^^^^^^^^^^^^
  File "/usr/local/lib/python3.12/smtplib.py", line 312, in _get_socket
    return socket.create_connection((host, port), timeout,
           ^^^^^^^^^^^^^^^^^^^^^^^^^^^^^^^^^^^^^^^^^^^^^^^
  File "/usr/local/lib/python3.12/socket.py", line 852, in create_connection
    raise exceptions[0]
  File "/usr/local/lib/python3.12/socket.py", line 837, in create_connection
    sock.connect(sa)
ConnectionRefusedError: [Errno 111] Connection refused

During handling of the above exception, another exception occurred:

Traceback (most recent call last):
  File "/home/airflow/.local/lib/python3.12/site-packages/airflow/models/taskinstance.py", line 877, in _handle_failure
    task_instance.email_alert(error, failure_context["task"])
  File "/home/airflow/.local/lib/python3.12/site-packages/airflow/models/taskinstance.py", line 3163, in email_alert
    _email_alert(task_instance=self, exception=exception, task=task)
  File "/home/airflow/.local/lib/python3.12/site-packages/airflow/models/taskinstance.py", line 1065, in _email_alert
    send_email(task.email, subject, html_content_err)
  File "/home/airflow/.local/lib/python3.12/site-packages/airflow/utils/email.py", line 80, in send_email
    return backend(
           ^^^^^^^^
  File "/home/airflow/.local/lib/python3.12/site-packages/airflow/utils/email.py", line 154, in send_email_smtp
    send_mime_email(e_from=mail_from, e_to=recipients, mime_msg=msg, conn_id=conn_id, dryrun=dryrun)
  File "/home/airflow/.local/lib/python3.12/site-packages/airflow/utils/email.py", line 273, in send_mime_email
    smtp_conn = _get_smtp_connection(smtp_host, smtp_port, smtp_timeout, smtp_ssl)
                ^^^^^^^^^^^^^^^^^^^^^^^^^^^^^^^^^^^^^^^^^^^^^^^^^^^^^^^^^^^^^^^^^^
  File "/home/airflow/.local/lib/python3.12/site-packages/airflow/utils/email.py", line 317, in _get_smtp_connection
    return smtplib.SMTP(host=host, port=port, timeout=timeout)
           ^^^^^^^^^^^^^^^^^^^^^^^^^^^^^^^^^^^^^^^^^^^^^^^^^^^
  File "/usr/local/lib/python3.12/smtplib.py", line 255, in __init__
    (code, msg) = self.connect(host, port)
                  ^^^^^^^^^^^^^^^^^^^^^^^^
  File "/usr/local/lib/python3.12/smtplib.py", line 341, in connect
    self.sock = self._get_socket(host, port, self.timeout)
                ^^^^^^^^^^^^^^^^^^^^^^^^^^^^^^^^^^^^^^^^^^
  File "/usr/local/lib/python3.12/smtplib.py", line 312, in _get_socket
    return socket.create_connection((host, port), timeout,
           ^^^^^^^^^^^^^^^^^^^^^^^^^^^^^^^^^^^^^^^^^^^^^^^
  File "/usr/local/lib/python3.12/socket.py", line 852, in create_connection
    raise exceptions[0]
  File "/usr/local/lib/python3.12/socket.py", line 837, in create_connection
    sock.connect(sa)
ConnectionRefusedError: [Errno 111] Connection refused
[2025-07-19T21:38:29.540+0000] {standard_task_runner.py:110} ERROR - Failed to execute job 19 for task force_data_update (Forced update failed: With n_samples=0, test_size=0.2 and train_size=None, the resulting train set will be empty. Adjust any of the aforementioned parameters.; 410)
[2025-07-19T21:38:29.703+0000] {local_task_job_runner.py:240} INFO - Task exited with return code 1
[2025-07-19T21:38:29.869+0000] {taskinstance.py:3498} INFO - 1 downstream tasks scheduled from follow-on schedule check
[2025-07-19T21:38:29.876+0000] {local_task_job_runner.py:222} INFO - ::endgroup::
