[2025-07-19T21:07:57.180+0000] {local_task_job_runner.py:120} INFO - ::group::Pre task execution logs
[2025-07-19T21:07:57.231+0000] {taskinstance.py:2076} INFO - Dependencies all met for dep_context=non-requeueable deps ti=<TaskInstance: nog_weekly_prediction.run_weekly_prediction manual__2025-07-19T21:02:46.694726+00:00 [queued]>
[2025-07-19T21:07:57.238+0000] {taskinstance.py:2076} INFO - Dependencies all met for dep_context=requeueable deps ti=<TaskInstance: nog_weekly_prediction.run_weekly_prediction manual__2025-07-19T21:02:46.694726+00:00 [queued]>
[2025-07-19T21:07:57.239+0000] {taskinstance.py:2306} INFO - Starting attempt 2 of 2
[2025-07-19T21:07:57.250+0000] {taskinstance.py:2330} INFO - Executing <Task(PythonOperator): run_weekly_prediction> on 2025-07-19 21:02:46.694726+00:00
[2025-07-19T21:07:57.273+0000] {standard_task_runner.py:63} INFO - Started process 610 to run task
[2025-07-19T21:07:57.277+0000] {standard_task_runner.py:90} INFO - Running: ['***', 'tasks', 'run', 'nog_weekly_prediction', 'run_weekly_prediction', 'manual__2025-07-19T21:02:46.694726+00:00', '--job-id', '8', '--raw', '--subdir', 'DAGS_FOLDER/nog_weekly_prediction_dag.py', '--cfg-path', '/tmp/tmpm5slerfm']
[2025-07-19T21:07:57.282+0000] {standard_task_runner.py:91} INFO - Job 8: Subtask run_weekly_prediction
[2025-07-19T21:07:57.348+0000] {task_command.py:426} INFO - Running <TaskInstance: nog_weekly_prediction.run_weekly_prediction manual__2025-07-19T21:02:46.694726+00:00 [running]> on host bf9bc2029e47
[2025-07-19T21:07:57.410+0000] {taskinstance.py:2648} INFO - Exporting env vars: AIRFLOW_CTX_DAG_EMAIL='your-email@example.com' AIRFLOW_CTX_DAG_OWNER='nog_team' AIRFLOW_CTX_DAG_ID='nog_weekly_prediction' AIRFLOW_CTX_TASK_ID='run_weekly_prediction' AIRFLOW_CTX_EXECUTION_DATE='2025-07-19T21:02:46.694726+00:00' AIRFLOW_CTX_TRY_NUMBER='2' AIRFLOW_CTX_DAG_RUN_ID='manual__2025-07-19T21:02:46.694726+00:00'
[2025-07-19T21:07:57.411+0000] {taskinstance.py:430} INFO - ::endgroup::
[2025-07-19T21:07:57.430+0000] {nog_weekly_prediction_dag.py:43} INFO - Starting weekly NOG prediction pipeline...
[2025-07-19T21:07:57.430+0000] {weekly_predict.py:336} INFO - Starting weekly prediction pipeline...
[2025-07-19T21:07:57.431+0000] {weekly_predict.py:112} INFO - Fetching data (update_csv=False)...
[2025-07-19T21:07:57.443+0000] {weekly_predict.py:120} ERROR - Error fetching data: [Errno 2] No such file or directory: 'data/NOG.csv'
[2025-07-19T21:07:57.444+0000] {weekly_predict.py:377} ERROR - Pipeline failed: [Errno 2] No such file or directory: 'data/NOG.csv'
[2025-07-19T21:07:57.444+0000] {nog_weekly_prediction_dag.py:70} ERROR - ❌ Pipeline failed: [Errno 2] No such file or directory: 'data/NOG.csv'
[2025-07-19T21:07:57.445+0000] {nog_weekly_prediction_dag.py:74} ERROR - ❌ Error in weekly prediction pipeline: Pipeline failed: [Errno 2] No such file or directory: 'data/NOG.csv'
[2025-07-19T21:07:57.445+0000] {taskinstance.py:441} INFO - ::group::Post task execution logs
[2025-07-19T21:07:57.446+0000] {taskinstance.py:2905} ERROR - Task failed with exception
Traceback (most recent call last):
  File "/home/airflow/.local/lib/python3.12/site-packages/airflow/models/taskinstance.py", line 465, in _execute_task
    result = _execute_callable(context=context, **execute_callable_kwargs)
             ^^^^^^^^^^^^^^^^^^^^^^^^^^^^^^^^^^^^^^^^^^^^^^^^^^^^^^^^^^^^^
  File "/home/airflow/.local/lib/python3.12/site-packages/airflow/models/taskinstance.py", line 432, in _execute_callable
    return execute_callable(context=context, **execute_callable_kwargs)
           ^^^^^^^^^^^^^^^^^^^^^^^^^^^^^^^^^^^^^^^^^^^^^^^^^^^^^^^^^^^^
  File "/home/airflow/.local/lib/python3.12/site-packages/airflow/models/baseoperator.py", line 400, in wrapper
    return func(self, *args, **kwargs)
           ^^^^^^^^^^^^^^^^^^^^^^^^^^^
  File "/home/airflow/.local/lib/python3.12/site-packages/airflow/operators/python.py", line 235, in execute
    return_value = self.execute_callable()
                   ^^^^^^^^^^^^^^^^^^^^^^^
  File "/home/airflow/.local/lib/python3.12/site-packages/airflow/operators/python.py", line 252, in execute_callable
    return self.python_callable(*self.op_args, **self.op_kwargs)
           ^^^^^^^^^^^^^^^^^^^^^^^^^^^^^^^^^^^^^^^^^^^^^^^^^^^^^
  File "/opt/airflow/dags/nog_weekly_prediction_dag.py", line 71, in run_weekly_prediction
    raise Exception(error_msg)
Exception: Pipeline failed: [Errno 2] No such file or directory: 'data/NOG.csv'
[2025-07-19T21:07:57.461+0000] {taskinstance.py:1206} INFO - Marking task as FAILED. dag_id=nog_weekly_prediction, task_id=run_weekly_prediction, run_id=manual__2025-07-19T21:02:46.694726+00:00, execution_date=20250719T210246, start_date=20250719T210757, end_date=20250719T210757
[2025-07-19T21:07:57.480+0000] {configuration.py:1050} WARNING - section/key [smtp/smtp_user] not found in config
[2025-07-19T21:07:57.481+0000] {email.py:271} INFO - Email alerting: attempt 1
[2025-07-19T21:07:57.491+0000] {configuration.py:1050} WARNING - section/key [smtp/smtp_user] not found in config
[2025-07-19T21:07:57.491+0000] {email.py:271} INFO - Email alerting: attempt 1
[2025-07-19T21:07:57.492+0000] {taskinstance.py:879} ERROR - Failed to send email to: ['your-email@example.com']
Traceback (most recent call last):
  File "/home/airflow/.local/lib/python3.12/site-packages/airflow/models/taskinstance.py", line 2479, in _run_raw_task
    self._execute_task_with_callbacks(context, test_mode, session=session)
  File "/home/airflow/.local/lib/python3.12/site-packages/airflow/models/taskinstance.py", line 2676, in _execute_task_with_callbacks
    result = self._execute_task(context, task_orig)
             ^^^^^^^^^^^^^^^^^^^^^^^^^^^^^^^^^^^^^^
  File "/home/airflow/.local/lib/python3.12/site-packages/airflow/models/taskinstance.py", line 2701, in _execute_task
    return _execute_task(self, context, task_orig)
           ^^^^^^^^^^^^^^^^^^^^^^^^^^^^^^^^^^^^^^^
  File "/home/airflow/.local/lib/python3.12/site-packages/airflow/models/taskinstance.py", line 465, in _execute_task
    result = _execute_callable(context=context, **execute_callable_kwargs)
             ^^^^^^^^^^^^^^^^^^^^^^^^^^^^^^^^^^^^^^^^^^^^^^^^^^^^^^^^^^^^^
  File "/home/airflow/.local/lib/python3.12/site-packages/airflow/models/taskinstance.py", line 432, in _execute_callable
    return execute_callable(context=context, **execute_callable_kwargs)
           ^^^^^^^^^^^^^^^^^^^^^^^^^^^^^^^^^^^^^^^^^^^^^^^^^^^^^^^^^^^^
  File "/home/airflow/.local/lib/python3.12/site-packages/airflow/models/baseoperator.py", line 400, in wrapper
    return func(self, *args, **kwargs)
           ^^^^^^^^^^^^^^^^^^^^^^^^^^^
  File "/home/airflow/.local/lib/python3.12/site-packages/airflow/operators/python.py", line 235, in execute
    return_value = self.execute_callable()
                   ^^^^^^^^^^^^^^^^^^^^^^^
  File "/home/airflow/.local/lib/python3.12/site-packages/airflow/operators/python.py", line 252, in execute_callable
    return self.python_callable(*self.op_args, **self.op_kwargs)
           ^^^^^^^^^^^^^^^^^^^^^^^^^^^^^^^^^^^^^^^^^^^^^^^^^^^^^
  File "/opt/airflow/dags/nog_weekly_prediction_dag.py", line 71, in run_weekly_prediction
    raise Exception(error_msg)
Exception: Pipeline failed: [Errno 2] No such file or directory: 'data/NOG.csv'

During handling of the above exception, another exception occurred:

Traceback (most recent call last):
  File "/home/airflow/.local/lib/python3.12/site-packages/airflow/models/taskinstance.py", line 1063, in _email_alert
    send_email(task.email, subject, html_content)
  File "/home/airflow/.local/lib/python3.12/site-packages/airflow/utils/email.py", line 80, in send_email
    return backend(
           ^^^^^^^^
  File "/home/airflow/.local/lib/python3.12/site-packages/airflow/utils/email.py", line 154, in send_email_smtp
    send_mime_email(e_from=mail_from, e_to=recipients, mime_msg=msg, conn_id=conn_id, dryrun=dryrun)
  File "/home/airflow/.local/lib/python3.12/site-packages/airflow/utils/email.py", line 273, in send_mime_email
    smtp_conn = _get_smtp_connection(smtp_host, smtp_port, smtp_timeout, smtp_ssl)
                ^^^^^^^^^^^^^^^^^^^^^^^^^^^^^^^^^^^^^^^^^^^^^^^^^^^^^^^^^^^^^^^^^^
  File "/home/airflow/.local/lib/python3.12/site-packages/airflow/utils/email.py", line 317, in _get_smtp_connection
    return smtplib.SMTP(host=host, port=port, timeout=timeout)
           ^^^^^^^^^^^^^^^^^^^^^^^^^^^^^^^^^^^^^^^^^^^^^^^^^^^
  File "/usr/local/lib/python3.12/smtplib.py", line 255, in __init__
    (code, msg) = self.connect(host, port)
                  ^^^^^^^^^^^^^^^^^^^^^^^^
  File "/usr/local/lib/python3.12/smtplib.py", line 341, in connect
    self.sock = self._get_socket(host, port, self.timeout)
                ^^^^^^^^^^^^^^^^^^^^^^^^^^^^^^^^^^^^^^^^^^
  File "/usr/local/lib/python3.12/smtplib.py", line 312, in _get_socket
    return socket.create_connection((host, port), timeout,
           ^^^^^^^^^^^^^^^^^^^^^^^^^^^^^^^^^^^^^^^^^^^^^^^
  File "/usr/local/lib/python3.12/socket.py", line 852, in create_connection
    raise exceptions[0]
  File "/usr/local/lib/python3.12/socket.py", line 837, in create_connection
    sock.connect(sa)
ConnectionRefusedError: [Errno 111] Connection refused

During handling of the above exception, another exception occurred:

Traceback (most recent call last):
  File "/home/airflow/.local/lib/python3.12/site-packages/airflow/models/taskinstance.py", line 877, in _handle_failure
    task_instance.email_alert(error, failure_context["task"])
  File "/home/airflow/.local/lib/python3.12/site-packages/airflow/models/taskinstance.py", line 3163, in email_alert
    _email_alert(task_instance=self, exception=exception, task=task)
  File "/home/airflow/.local/lib/python3.12/site-packages/airflow/models/taskinstance.py", line 1065, in _email_alert
    send_email(task.email, subject, html_content_err)
  File "/home/airflow/.local/lib/python3.12/site-packages/airflow/utils/email.py", line 80, in send_email
    return backend(
           ^^^^^^^^
  File "/home/airflow/.local/lib/python3.12/site-packages/airflow/utils/email.py", line 154, in send_email_smtp
    send_mime_email(e_from=mail_from, e_to=recipients, mime_msg=msg, conn_id=conn_id, dryrun=dryrun)
  File "/home/airflow/.local/lib/python3.12/site-packages/airflow/utils/email.py", line 273, in send_mime_email
    smtp_conn = _get_smtp_connection(smtp_host, smtp_port, smtp_timeout, smtp_ssl)
                ^^^^^^^^^^^^^^^^^^^^^^^^^^^^^^^^^^^^^^^^^^^^^^^^^^^^^^^^^^^^^^^^^^
  File "/home/airflow/.local/lib/python3.12/site-packages/airflow/utils/email.py", line 317, in _get_smtp_connection
    return smtplib.SMTP(host=host, port=port, timeout=timeout)
           ^^^^^^^^^^^^^^^^^^^^^^^^^^^^^^^^^^^^^^^^^^^^^^^^^^^
  File "/usr/local/lib/python3.12/smtplib.py", line 255, in __init__
    (code, msg) = self.connect(host, port)
                  ^^^^^^^^^^^^^^^^^^^^^^^^
  File "/usr/local/lib/python3.12/smtplib.py", line 341, in connect
    self.sock = self._get_socket(host, port, self.timeout)
                ^^^^^^^^^^^^^^^^^^^^^^^^^^^^^^^^^^^^^^^^^^
  File "/usr/local/lib/python3.12/smtplib.py", line 312, in _get_socket
    return socket.create_connection((host, port), timeout,
           ^^^^^^^^^^^^^^^^^^^^^^^^^^^^^^^^^^^^^^^^^^^^^^^
  File "/usr/local/lib/python3.12/socket.py", line 852, in create_connection
    raise exceptions[0]
  File "/usr/local/lib/python3.12/socket.py", line 837, in create_connection
    sock.connect(sa)
ConnectionRefusedError: [Errno 111] Connection refused
[2025-07-19T21:07:57.504+0000] {standard_task_runner.py:110} ERROR - Failed to execute job 8 for task run_weekly_prediction (Pipeline failed: [Errno 2] No such file or directory: 'data/NOG.csv'; 610)
[2025-07-19T21:07:57.546+0000] {local_task_job_runner.py:240} INFO - Task exited with return code 1
[2025-07-19T21:07:57.556+0000] {local_task_job_runner.py:222} INFO - ::endgroup::
