[2025-07-19T21:02:52.565+0000] {local_task_job_runner.py:120} INFO - ::group::Pre task execution logs
[2025-07-19T21:02:52.673+0000] {taskinstance.py:2076} INFO - Dependencies all met for dep_context=non-requeueable deps ti=<TaskInstance: nog_weekly_prediction.force_data_update manual__2025-07-19T21:02:46.694726+00:00 [queued]>
[2025-07-19T21:02:52.687+0000] {taskinstance.py:2076} INFO - Dependencies all met for dep_context=requeueable deps ti=<TaskInstance: nog_weekly_prediction.force_data_update manual__2025-07-19T21:02:46.694726+00:00 [queued]>
[2025-07-19T21:02:52.688+0000] {taskinstance.py:2306} INFO - Starting attempt 1 of 2
[2025-07-19T21:02:52.705+0000] {taskinstance.py:2330} INFO - Executing <Task(PythonOperator): force_data_update> on 2025-07-19 21:02:46.694726+00:00
[2025-07-19T21:02:52.721+0000] {standard_task_runner.py:63} INFO - Started process 384 to run task
[2025-07-19T21:02:52.725+0000] {standard_task_runner.py:90} INFO - Running: ['***', 'tasks', 'run', 'nog_weekly_prediction', 'force_data_update', 'manual__2025-07-19T21:02:46.694726+00:00', '--job-id', '5', '--raw', '--subdir', 'DAGS_FOLDER/nog_weekly_prediction_dag.py', '--cfg-path', '/tmp/tmpps8fnktn']
[2025-07-19T21:02:52.730+0000] {standard_task_runner.py:91} INFO - Job 5: Subtask force_data_update
[2025-07-19T21:02:52.840+0000] {task_command.py:426} INFO - Running <TaskInstance: nog_weekly_prediction.force_data_update manual__2025-07-19T21:02:46.694726+00:00 [running]> on host bf9bc2029e47
[2025-07-19T21:02:53.371+0000] {taskinstance.py:2648} INFO - Exporting env vars: AIRFLOW_CTX_DAG_EMAIL='your-email@example.com' AIRFLOW_CTX_DAG_OWNER='nog_team' AIRFLOW_CTX_DAG_ID='nog_weekly_prediction' AIRFLOW_CTX_TASK_ID='force_data_update' AIRFLOW_CTX_EXECUTION_DATE='2025-07-19T21:02:46.694726+00:00' AIRFLOW_CTX_TRY_NUMBER='1' AIRFLOW_CTX_DAG_RUN_ID='manual__2025-07-19T21:02:46.694726+00:00'
[2025-07-19T21:02:53.379+0000] {taskinstance.py:430} INFO - ::endgroup::
[2025-07-19T21:02:53.537+0000] {nog_weekly_prediction_dag.py:82} INFO - üîÑ Forcing data update...
[2025-07-19T21:02:53.541+0000] {nog_weekly_prediction_dag.py:100} ERROR - ‚ùå Error in forced data update: 'WeeklyPredictionPipeline' object has no attribute 'run_pipeline'
[2025-07-19T21:02:53.544+0000] {taskinstance.py:441} INFO - ::group::Post task execution logs
[2025-07-19T21:02:53.548+0000] {taskinstance.py:2905} ERROR - Task failed with exception
Traceback (most recent call last):
  File "/home/airflow/.local/lib/python3.12/site-packages/airflow/models/taskinstance.py", line 465, in _execute_task
    result = _execute_callable(context=context, **execute_callable_kwargs)
             ^^^^^^^^^^^^^^^^^^^^^^^^^^^^^^^^^^^^^^^^^^^^^^^^^^^^^^^^^^^^^
  File "/home/airflow/.local/lib/python3.12/site-packages/airflow/models/taskinstance.py", line 432, in _execute_callable
    return execute_callable(context=context, **execute_callable_kwargs)
           ^^^^^^^^^^^^^^^^^^^^^^^^^^^^^^^^^^^^^^^^^^^^^^^^^^^^^^^^^^^^
  File "/home/airflow/.local/lib/python3.12/site-packages/airflow/models/baseoperator.py", line 400, in wrapper
    return func(self, *args, **kwargs)
           ^^^^^^^^^^^^^^^^^^^^^^^^^^^
  File "/home/airflow/.local/lib/python3.12/site-packages/airflow/operators/python.py", line 235, in execute
    return_value = self.execute_callable()
                   ^^^^^^^^^^^^^^^^^^^^^^^
  File "/home/airflow/.local/lib/python3.12/site-packages/airflow/operators/python.py", line 252, in execute_callable
    return self.python_callable(*self.op_args, **self.op_kwargs)
           ^^^^^^^^^^^^^^^^^^^^^^^^^^^^^^^^^^^^^^^^^^^^^^^^^^^^^
  File "/opt/airflow/dags/nog_weekly_prediction_dag.py", line 88, in force_data_update
    results = pipeline.run_pipeline(update_data=True)
              ^^^^^^^^^^^^^^^^^^^^^
AttributeError: 'WeeklyPredictionPipeline' object has no attribute 'run_pipeline'
[2025-07-19T21:02:53.637+0000] {taskinstance.py:1206} INFO - Marking task as UP_FOR_RETRY. dag_id=nog_weekly_prediction, task_id=force_data_update, run_id=manual__2025-07-19T21:02:46.694726+00:00, execution_date=20250719T210246, start_date=20250719T210252, end_date=20250719T210253
[2025-07-19T21:02:53.690+0000] {standard_task_runner.py:110} ERROR - Failed to execute job 5 for task force_data_update ('WeeklyPredictionPipeline' object has no attribute 'run_pipeline'; 384)
[2025-07-19T21:02:53.744+0000] {local_task_job_runner.py:240} INFO - Task exited with return code 1
[2025-07-19T21:02:53.852+0000] {taskinstance.py:3498} INFO - 0 downstream tasks scheduled from follow-on schedule check
[2025-07-19T21:02:53.854+0000] {local_task_job_runner.py:222} INFO - ::endgroup::
